<?xml version="1.0" ?>
<!-- =================================================================================== -->
<!-- |    This document was autogenerated by xacro from ur10_ensenso_vgs.urdf.xacro    | -->
<!-- |    EDITING THIS FILE BY HAND IS NOT RECOMMENDED                                 | -->
<!-- =================================================================================== -->
<robot name="ur10" xmlns:xacro="http://ros.org/wiki/xacro">
  <!-- common stuff -->
  <gazebo>
    <plugin filename="libgazebo_ros_control.so" name="ros_control">
      <!--robotNamespace>/</robotNamespace-->
      <!--robotSimType>gazebo_ros_control/DefaultRobotHWSim</robotSimType-->
    </plugin>
    <!--
    <plugin name="gazebo_ros_power_monitor_controller" filename="libgazebo_ros_power_monitor.so">
      <alwaysOn>true</alwaysOn>
      <updateRate>1.0</updateRate>
      <timeout>5</timeout>
      <powerStateTopic>power_state</powerStateTopic>
      <powerStateRate>10.0</powerStateRate>
      <fullChargeCapacity>87.78</fullChargeCapacity>     
      <dischargeRate>-474</dischargeRate>
      <chargeRate>525</chargeRate>
      <dischargeVoltage>15.52</dischargeVoltage>
      <chargeVoltage>16.41</chargeVoltage>
    </plugin>
-->
  </gazebo>
  <!-- ur10 -->
  <!--
  Author: Kelsey Hawkins 
  Contributers: Jimmy Da Silva, Ajit Krisshna N L, Muhammad Asif Rana 
-->
  <!-- Inertia parameters -->
  <!-- This mass might be incorrect -->
  <!-- These parameters are borrowed from the urcontrol.conf file
       but are not verified for the correct permutation.
       The permutation was guessed by looking at the UR5 parameters.
       Serious use of these parameters needs further inspection. -->
  <!-- Kinematic model -->
  <!-- Properties from urcontrol.conf -->
  <!-- Arbitrary offsets for shoulder/elbow joints -->
  <!-- measured from model -->
  <!-- measured from model -->
  <!-- link lengths used in model -->
  <!-- 3d sensor setup -->
  <material name="blue">
    <color rgba="0 0 0.8 1"/>
  </material>
  <material name="grey">
    <color rgba="0.25 0.25 0.25 1"/>
  </material>
  <!-- arm extras -->
  <!-- vgs gripper system -->
  <!-- arm -->
  <link name="base_link">
    <visual>
      <geometry>
        <mesh filename="package://ur_description/meshes/ur10/visual/base.dae"/>
      </geometry>
      <material name="LightGrey">
        <color rgba="0.7 0.7 0.7 1.0"/>
      </material>
    </visual>
    <collision>
      <geometry>
        <mesh filename="package://ur_description/meshes/ur10/collision/base.stl"/>
      </geometry>
    </collision>
    <inertial>
      <mass value="4.0"/>
      <origin rpy="0 0 0" xyz="0.0 0.0 0.0"/>
      <inertia ixx="0.0061063308908" ixy="0.0" ixz="0.0" iyy="0.0061063308908" iyz="0.0" izz="0.01125"/>
    </inertial>
  </link>
  <joint name="shoulder_pan_joint" type="revolute">
    <parent link="base_link"/>
    <child link="shoulder_link"/>
    <origin rpy="0.0 0.0 0.0" xyz="0.0 0.0 0.1273"/>
    <axis xyz="0 0 1"/>
    <limit effort="330.0" lower="-6.2831853" upper="6.2831853" velocity="2.16"/>
    <dynamics damping="0.0" friction="0.0"/>
  </joint>
  <link name="shoulder_link">
    <visual>
      <geometry>
        <mesh filename="package://ur_description/meshes/ur10/visual/shoulder.dae"/>
      </geometry>
      <material name="LightGrey">
        <color rgba="0.7 0.7 0.7 1.0"/>
      </material>
    </visual>
    <collision>
      <geometry>
        <mesh filename="package://ur_description/meshes/ur10/collision/shoulder.stl"/>
      </geometry>
    </collision>
    <inertial>
      <mass value="7.778"/>
      <origin rpy="0 0 0" xyz="0.0 0.0 0.0"/>
      <inertia ixx="0.0314743125769" ixy="0.0" ixz="0.0" iyy="0.0314743125769" iyz="0.0" izz="0.021875625"/>
    </inertial>
  </link>
  <joint name="shoulder_lift_joint" type="revolute">
    <parent link="shoulder_link"/>
    <child link="upper_arm_link"/>
    <origin rpy="0.0 1.570796325 0.0" xyz="0.0 0.220941 0.0"/>
    <axis xyz="0 1 0"/>
    <limit effort="330.0" lower="-6.2831853" upper="6.2831853" velocity="2.16"/>
    <dynamics damping="0.0" friction="0.0"/>
  </joint>
  <link name="upper_arm_link">
    <visual>
      <geometry>
        <mesh filename="package://ur_description/meshes/ur10/visual/upperarm.dae"/>
      </geometry>
      <material name="LightGrey">
        <color rgba="0.7 0.7 0.7 1.0"/>
      </material>
    </visual>
    <collision>
      <geometry>
        <mesh filename="package://ur_description/meshes/ur10/collision/upperarm.stl"/>
      </geometry>
    </collision>
    <inertial>
      <mass value="12.93"/>
      <origin rpy="0 0 0" xyz="0.0 0.0 0.306"/>
      <inertia ixx="0.421753803798" ixy="0.0" ixz="0.0" iyy="0.421753803798" iyz="0.0" izz="0.036365625"/>
    </inertial>
  </link>
  <joint name="elbow_joint" type="revolute">
    <parent link="upper_arm_link"/>
    <child link="forearm_link"/>
    <origin rpy="0.0 0.0 0.0" xyz="0.0 -0.1719 0.612"/>
    <axis xyz="0 1 0"/>
    <limit effort="150.0" lower="-6.2831853" upper="6.2831853" velocity="3.15"/>
    <dynamics damping="0.0" friction="0.0"/>
  </joint>
  <link name="forearm_link">
    <visual>
      <geometry>
        <mesh filename="package://ur_description/meshes/ur10/visual/forearm.dae"/>
      </geometry>
      <material name="LightGrey">
        <color rgba="0.7 0.7 0.7 1.0"/>
      </material>
    </visual>
    <collision>
      <geometry>
        <mesh filename="package://ur_description/meshes/ur10/collision/forearm.stl"/>
      </geometry>
    </collision>
    <inertial>
      <mass value="3.87"/>
      <origin rpy="0 0 0" xyz="0.0 0.0 0.28615"/>
      <inertia ixx="0.111069694097" ixy="0.0" ixz="0.0" iyy="0.111069694097" iyz="0.0" izz="0.010884375"/>
    </inertial>
  </link>
  <joint name="wrist_1_joint" type="revolute">
    <parent link="forearm_link"/>
    <child link="wrist_1_link"/>
    <origin rpy="0.0 1.570796325 0.0" xyz="0.0 0.0 0.5723"/>
    <axis xyz="0 1 0"/>
    <limit effort="54.0" lower="-6.2831853" upper="6.2831853" velocity="3.2"/>
    <dynamics damping="0.0" friction="0.0"/>
  </joint>
  <link name="wrist_1_link">
    <visual>
      <geometry>
        <mesh filename="package://ur_description/meshes/ur10/visual/wrist1.dae"/>
      </geometry>
      <material name="LightGrey">
        <color rgba="0.7 0.7 0.7 1.0"/>
      </material>
    </visual>
    <collision>
      <geometry>
        <mesh filename="package://ur_description/meshes/ur10/collision/wrist1.stl"/>
      </geometry>
    </collision>
    <inertial>
      <mass value="1.96"/>
      <origin rpy="0 0 0" xyz="0.0 0.0 0.0"/>
      <inertia ixx="0.0051082479567" ixy="0.0" ixz="0.0" iyy="0.0051082479567" iyz="0.0" izz="0.0055125"/>
    </inertial>
  </link>
  <joint name="wrist_2_joint" type="revolute">
    <parent link="wrist_1_link"/>
    <child link="wrist_2_link"/>
    <origin rpy="0.0 0.0 0.0" xyz="0.0 0.1149 0.0"/>
    <axis xyz="0 0 1"/>
    <limit effort="54.0" lower="-6.2831853" upper="6.2831853" velocity="3.2"/>
    <dynamics damping="0.0" friction="0.0"/>
  </joint>
  <link name="wrist_2_link">
    <visual>
      <geometry>
        <mesh filename="package://ur_description/meshes/ur10/visual/wrist2.dae"/>
      </geometry>
      <material name="LightGrey">
        <color rgba="0.7 0.7 0.7 1.0"/>
      </material>
    </visual>
    <collision>
      <geometry>
        <mesh filename="package://ur_description/meshes/ur10/collision/wrist2.stl"/>
      </geometry>
    </collision>
    <inertial>
      <mass value="1.96"/>
      <origin rpy="0 0 0" xyz="0.0 0.0 0.0"/>
      <inertia ixx="0.0051082479567" ixy="0.0" ixz="0.0" iyy="0.0051082479567" iyz="0.0" izz="0.0055125"/>
    </inertial>
  </link>
  <joint name="wrist_3_joint" type="revolute">
    <parent link="wrist_2_link"/>
    <child link="wrist_3_link"/>
    <origin rpy="0.0 0.0 0.0" xyz="0.0 0.0 0.1157"/>
    <axis xyz="0 1 0"/>
    <limit effort="54.0" lower="-6.2831853" upper="6.2831853" velocity="3.2"/>
    <dynamics damping="0.0" friction="0.0"/>
  </joint>
  <link name="wrist_3_link">
    <visual>
      <geometry>
        <mesh filename="package://ur_description/meshes/ur10/visual/wrist3.dae"/>
      </geometry>
      <material name="LightGrey">
        <color rgba="0.7 0.7 0.7 1.0"/>
      </material>
    </visual>
    <collision>
      <geometry>
        <mesh filename="package://ur_description/meshes/ur10/collision/wrist3.stl"/>
      </geometry>
    </collision>
    <inertial>
      <mass value="0.202"/>
      <origin rpy="0 0 0" xyz="0.0 0.0 0.0"/>
      <inertia ixx="0.000526462289415" ixy="0.0" ixz="0.0" iyy="0.000526462289415" iyz="0.0" izz="0.000568125"/>
    </inertial>
  </link>
  <joint name="ee_fixed_joint" type="fixed">
    <parent link="wrist_3_link"/>
    <child link="ee_link"/>
    <origin rpy="0.0 0.0 1.570796325" xyz="0.0 0.0922 0.0"/>
  </joint>
  <link name="ee_link">
    <collision>
      <geometry>
        <box size="0.01 0.01 0.01"/>
      </geometry>
      <origin rpy="0 0 0" xyz="-0.01 0 0"/>
    </collision>
  </link>
  <transmission name="shoulder_pan_trans">
    <type>transmission_interface/SimpleTransmission</type>
    <joint name="shoulder_pan_joint">
      <hardwareInterface>PositionJointInterface</hardwareInterface>
    </joint>
    <actuator name="shoulder_pan_motor">
      <mechanicalReduction>1</mechanicalReduction>
    </actuator>
  </transmission>
  <transmission name="shoulder_lift_trans">
    <type>transmission_interface/SimpleTransmission</type>
    <joint name="shoulder_lift_joint">
      <hardwareInterface>PositionJointInterface</hardwareInterface>
    </joint>
    <actuator name="shoulder_lift_motor">
      <mechanicalReduction>1</mechanicalReduction>
    </actuator>
  </transmission>
  <transmission name="elbow_trans">
    <type>transmission_interface/SimpleTransmission</type>
    <joint name="elbow_joint">
      <hardwareInterface>PositionJointInterface</hardwareInterface>
    </joint>
    <actuator name="elbow_motor">
      <mechanicalReduction>1</mechanicalReduction>
    </actuator>
  </transmission>
  <transmission name="wrist_1_trans">
    <type>transmission_interface/SimpleTransmission</type>
    <joint name="wrist_1_joint">
      <hardwareInterface>PositionJointInterface</hardwareInterface>
    </joint>
    <actuator name="wrist_1_motor">
      <mechanicalReduction>1</mechanicalReduction>
    </actuator>
  </transmission>
  <transmission name="wrist_2_trans">
    <type>transmission_interface/SimpleTransmission</type>
    <joint name="wrist_2_joint">
      <hardwareInterface>PositionJointInterface</hardwareInterface>
    </joint>
    <actuator name="wrist_2_motor">
      <mechanicalReduction>1</mechanicalReduction>
    </actuator>
  </transmission>
  <transmission name="wrist_3_trans">
    <type>transmission_interface/SimpleTransmission</type>
    <joint name="wrist_3_joint">
      <hardwareInterface>PositionJointInterface</hardwareInterface>
    </joint>
    <actuator name="wrist_3_motor">
      <mechanicalReduction>1</mechanicalReduction>
    </actuator>
  </transmission>
  <!-- nothing to do here at the moment -->
  <!-- ROS base_link to UR 'Base' Coordinates transform -->
  <link name="base"/>
  <joint name="base_link-base_fixed_joint" type="fixed">
    <!-- NOTE: this rotation is only needed as long as base_link itself is
                 not corrected wrt the real robot (ie: rotated over 180
                 degrees)
      -->
    <origin rpy="0 0 -3.14159265" xyz="0 0 0"/>
    <parent link="base_link"/>
    <child link="base"/>
  </joint>
  <!-- Frame coincident with all-zeros TCP on UR controller -->
  <link name="tool0"/>
  <joint name="wrist_3_link-tool0_fixed_joint" type="fixed">
    <origin rpy="-1.570796325 0 0" xyz="0 0.0922 0"/>
    <parent link="wrist_3_link"/>
    <child link="tool0"/>
  </joint>
  <!-- 3D sensor -->
  <!-- prefix can be used in case of multiple sensors -->
  <joint name="ensenso_joint" type="fixed">
    <origin rpy="3.14159265 0 0" xyz="0 0 0.038"/>
    <parent link="sensor3d_back_link"/>
    <child link="ensenso_link"/>
  </joint>
  <link name="ensenso_link">
    <visual>
      <origin rpy="0 0 0" xyz="0.026 0.0 0"/>
      <!-- Always check placing of the collision box by seeing it in the visual, uncomment below place box in visual and then keep same dimensions in the collision parameter-->
      <geometry>
        <box size="0.052 0.175 0.05"/>
      </geometry>
      <material name="blue"/>
    </visual>
    <collision>
      <origin rpy="0 0 0" xyz="0.026 0.0 0"/>
      <geometry>
        <box size="0.052 0.175 0.05"/>
      </geometry>
    </collision>
    <inertial>
      <mass value="0.5"/>
      <origin xyz="0 0 0"/>
      <inertia ixx="0.003881243" ixy="0.0" ixz="0.0" iyy="0.000498940" iyz="0.0" izz="0.003879257"/>
    </inertial>
  </link>
  <joint name="foscam_joint" type="fixed">
    <origin rpy="3.14159265 0 0" xyz="0 0 0.0905"/>
    <parent link="sensor3d_back_link"/>
    <child link="foscam_link"/>
  </joint>
  <link name="foscam_link">
    <visual>
      <origin rpy="0 0 0" xyz="0.026 0.0 0"/>
      <geometry>
        <box size="0.052 0.052 0.055"/>
      </geometry>
      <material name="grey"/>
    </visual>
    <collision>
      <origin rpy="0 0 0" xyz="0.026 0.0 0"/>
      <geometry>
        <box size="0.052 0.052 0.055"/>
      </geometry>
    </collision>
    <inertial>
      <mass value="0.1"/>
      <origin xyz="0 0 0"/>
      <inertia ixx="0.003881243" ixy="0.0" ixz="0.0" iyy="0.000498940" iyz="0.0" izz="0.003879257"/>
    </inertial>
  </link>
  <!-- The fixed joints & links below are usually published by static_transformers launched by the OpenNi launch 
         files. However, for Gazebo simulation we need them, so we add them here.
         (Hence, don't publish them additionally!) -->
  <!--joint name="camera_link_joint" type="fixed">
    	  <parent link="${prefix}kinect_link"/>
	  <child link="${prefix}camera_link"/>
    	  <origin rpy="-1.570796325 0.0 0.0" xyz="0.0605 0.015 -0.0325" />
	</joint>
	<link name="${prefix}camera_link"/>
	
	<joint name="camera_rgb_joint" type="fixed">
	  <origin xyz="0 -0.045 0" rpy="0 0 0" />
          <parent link="${prefix}camera_link"/>
      	  <child link="${prefix}camera_rgb_frame" />
    	</joint>
    	<link name="${prefix}camera_rgb_frame"/>

    	<joint name="camera_rgb_optical_joint" type="fixed">
      	  <origin xyz="0 0 0" rpy="${-M_PI/2} 0 ${-M_PI/2}" />
      	  <parent link="${prefix}camera_rgb_frame" />
      	  <child link="${prefix}camera_rgb_optical_frame" />
    	</joint>
    	<link name="${prefix}camera_rgb_optical_frame"/>

	<joint name="camera_depth_joint" type="fixed">
	  <origin xyz="0 -0.02 0" rpy="0 0 0" />
	  <parent link="${prefix}camera_link" />
	  <child link="${prefix}camera_depth_frame" />
	</joint>
	<link name="${prefix}camera_depth_frame"/>

	<joint name="camera_depth_optical_joint" type="fixed">
	  <origin xyz="0 0 0" rpy="${-M_PI/2} 0 ${-M_PI/2}" />
	  <parent link="${prefix}camera_depth_frame" />
	  <child link="${prefix}camera_depth_optical_frame" />
	</joint>
	<link name="${prefix}camera_depth_optical_frame"/-->
  <!-- arm extras -->
  <!-- NOTE: this rotation is only needed as long as base_link itself is
                 not corrected wrt the real robot (ie: rotated over 180
                 degrees)
      -->
  <link name="ground_base">
    <visual>
      <geometry>
        <box size="0.91 0.91 0.1"/>
      </geometry>
      <origin rpy="0 0 0" xyz="0 0 0.05"/>
      <material name="white">
        <color rgba="0.588235294118 0.588235294118 0.588235294118 1.0"/>
      </material>
    </visual>
    <collision>
      <geometry>
        <box size="0.91 0.91 0.1"/>
      </geometry>
      <origin rpy="0 0 0" xyz=" 0 0 0.05"/>
    </collision>
    <inertial>
      <origin rpy="0 0 0" xyz="0 0 0"/>
      <mass value="100"/>
      <inertia ixx="1" ixy="0" ixz="0" iyy="1" iyz="0" izz="1"/>
    </inertial>
  </link>
  <!-- ROS base_link to UR 'Base' Coordinates transform -->
  <joint name="base_pillar_joint" type="fixed">
    <origin rpy="0 0 0" xyz="0 0 0.1"/>
    <parent link="ground_base"/>
    <child link="base_pillar"/>
  </joint>
  <link name="base_pillar">
    <visual>
      <geometry>
        <box size=".15 .15 0.62"/>
      </geometry>
      <origin rpy="0 0 0" xyz="0 0 0.31"/>
      <material name="white">
        <color rgba="0.588235294118 0.588235294118 0.588235294118 1.0"/>
      </material>
    </visual>
    <collision>
      <geometry>
        <box size=".15 .15 0.62"/>
      </geometry>
      <origin rpy="0 0 0" xyz=" 0 0 0.31"/>
    </collision>
    <inertial>
      <origin rpy="0 0 0" xyz="0 0 0"/>
      <mass value="50"/>
      <inertia ixx="1" ixy="0" ixz="0" iyy="1" iyz="0" izz="1"/>
    </inertial>
  </link>
  <!-- define joint from base_pillar to base_link-->
  <joint name="base_link_joint" type="fixed">
    <origin rpy="0 0 0" xyz="0 0 0.62"/>
    <parent link="base_pillar"/>
    <child link="base_link"/>
  </joint>
  <!-- Transform link from arm to 3d sensor -->
  <joint name="sensor_tmp_joint" type="fixed">
    <!--origin rpy="-${M_PI*45/180} 0.0 0.0" xyz="0 0 0.0"/-->
    <origin rpy="0.0 0.0 0.0" xyz="0 0 0.0"/>
    <parent link="ee_link"/>
    <child link="sensor3d_rotate_link"/>
  </joint>
  <link name="sensor3d_rotate_link"/>
  <joint name="sensor3d_joint" type="fixed">
    <origin rpy="0.0 -0.174532925 0.0" xyz="0 0 0.075"/>
    <parent link="sensor3d_rotate_link"/>
    <child link="sensor3d_back_link"/>
  </joint>
  <link name="sensor3d_back_link"/>
  <!-- vgs gripper system -->
  <!-- venkat gripper suction -->
  <joint name="body_joint" type="fixed">
    <origin rpy="1.570796325 0 0" xyz="0.006 0 0"/>
    <parent link="ee_link"/>
    <child link="gs_body_link"/>
  </joint>
  <link name="gs_body_link">
    <visual>
      <origin rpy="0 0 0" xyz="-0.0055 0.0 0.0"/>
      <geometry>
        <mesh filename="package://iitktcs_robot_description/meshes/gripper_design_2/main_body_updated.dae" scale="0.001 0.001 0.001"/>
      </geometry>
      <material name="White">
        <color rgba="0.588235294118 0.588235294118 0.588235294118 1.0"/>
      </material>
    </visual>
    <collision>
      <origin rpy="0 0 0" xyz="-0.0055 0.0 0.0"/>
      <geometry>
        <mesh filename="package://iitktcs_robot_description/meshes/gripper_design_2/main_body_updated.STL" scale="0.001 0.001 0.001"/>
      </geometry>
    </collision>
    <inertial>
      <mass value="1"/>
      <inertia ixx="1" ixy="0.0" ixz="0.0" iyy="1" iyz="0.0" izz="1"/>
    </inertial>
  </link>
  <joint name="gripper_body_joint" type="prismatic">
    <origin rpy="1.570796325 0 0" xyz="0.006 0 0.0"/>
    <parent link="ee_link"/>
    <child link="gripper_body_link"/>
    <limit effort="1000.0" lower="0.0" upper="0.075" velocity="0.5"/>
  </joint>
  <link name="gripper_body_link">
    <visual>
      <origin rpy="0 -1.570796325 0" xyz="0.1595 0.0475 0.005"/>
      <geometry>
        <mesh filename="package://iitktcs_robot_description/meshes/gripper_design_2/gripper_l.dae" scale="0.001 0.001 0.001"/>
      </geometry>
      <material name="White">
        <color rgba="0.588235294118 0.588235294118 0.588235294118 1.0"/>
      </material>
    </visual>
    <collision>
      <origin rpy="0 -1.570796325 0" xyz="0.1495 0.0475 0.005"/>
      <geometry>
        <mesh filename="package://iitktcs_robot_description/meshes/gripper_design_2/gripper_l.STL" scale="0.001 0.001 0.001"/>
      </geometry>
    </collision>
    <inertial>
      <mass value="1"/>
      <inertia ixx="1" ixy="0.0" ixz="0.0" iyy="1" iyz="0.0" izz="1"/>
    </inertial>
  </link>
  <joint name="gripper_left_finger_joint" type="revolute">
    <origin rpy="0 0 0" xyz="0.1338 0.035 0"/>
    <parent link="gripper_body_link"/>
    <child link="left_finger_link"/>
    <axis xyz="0 1 0"/>
    <limit effort="150.0" lower="-0.12" upper="0.0" velocity="3.15"/>
    <dynamics damping="0.0" friction="0.0"/>
  </joint>
  <link name="left_finger_link">
    <visual>
      <!-- if you feel gripper opening is less then make pitch 11 degrees -->
      <origin rpy="0 0.18325957125 0" xyz="-0.002 0.0007 0.017"/>
      <geometry>
        <mesh filename="package://iitktcs_robot_description/meshes/gripper_design_2/left_gripper.dae" scale="0.001 0.001 0.001"/>
      </geometry>
      <material name="White">
        <color rgba="0.588235294118 0.588235294118 0.588235294118 1.0"/>
      </material>
    </visual>
    <collision>
      <!-- if you feel gripper opening is less then make pitch 11 degrees -->
      <origin rpy="0 0.18325957125 0" xyz="-0.002 0.0007 0.017"/>
      <geometry>
        <mesh filename="package://iitktcs_robot_description/meshes/gripper_design_2/left_gripper.STL" scale="0.001 0.001 0.001"/>
      </geometry>
    </collision>
    <inertial>
      <mass value="1"/>
      <inertia ixx="1" ixy="0.0" ixz="0.0" iyy="1" iyz="0.0" izz="1"/>
    </inertial>
  </link>
  <joint name="gripper_right_finger_joint" type="revolute">
    <origin rpy="0 0 0" xyz="0.1338 0.04 0"/>
    <parent link="gripper_body_link"/>
    <child link="right_finger_link"/>
    <axis xyz="0 1 0"/>
    <limit effort="150.0" lower="0.0" upper="0.18" velocity="3.15"/>
    <mimic joint="gripper_left_finger_joint" multiplier="-1.0" offset="0.0"/>
    <dynamics damping="0.0" friction="0.0"/>
  </joint>
  <link name="right_finger_link">
    <visual>
      <!-- if you feel gripper opening is less then make pitch 11 degrees -->
      <origin rpy="0 -0.18325957125 0" xyz="0.0 0.0035 -0.027"/>
      <geometry>
        <mesh filename="package://iitktcs_robot_description/meshes/gripper_design_2/right_gripper.dae" scale="0.001 0.001 0.001"/>
      </geometry>
      <material name="White">
        <color rgba="0.588235294118 0.588235294118 0.588235294118 1.0"/>
      </material>
    </visual>
    <collision>
      <!-- if you feel gripper opening is less then make pitch 11 degrees -->
      <origin rpy="0 -0.18325957125 0" xyz="0.0 0.0035 -0.027"/>
      <geometry>
        <mesh filename="package://iitktcs_robot_description/meshes/gripper_design_2/right_gripper.STL" scale="0.001 0.001 0.001"/>
      </geometry>
    </collision>
    <inertial>
      <mass value="1"/>
      <inertia ixx="1" ixy="0.0" ixz="0.0" iyy="1" iyz="0.0" izz="1"/>
    </inertial>
  </link>
  <joint name="suction_base_joint" type="revolute">
    <parent link="gs_body_link"/>
    <child link="suction_base_link"/>
    <origin rpy="0 0 0" xyz="0.322 0.00 0.0"/>
    <axis xyz="0 0 1"/>
    <limit effort="150.0" lower="0.0" upper="1.570796325" velocity="3.15"/>
    <dynamics damping="0.0" friction="0.0"/>
  </joint>
  <!-- IIT K -Changes for Stowing Operation -->
  <joint name="suction_suction2_joint" type="fixed">
    <parent link="gs_body_link"/>
    <child link="iitk_link"/>
    <origin rpy="1.570796325 0 0" xyz="0.322 0.00 0.0"/>
  </joint>
  <link name="iitk_link">
    
  </link>
  <!-- IIT K -Changes for Stowing Operation -->
  <link name="suction_base_link">
    <visual>
      <origin rpy="0 0 0" xyz="0.00 -0.027 0.0"/>
      <geometry>
        <mesh filename="package://iitktcs_robot_description/meshes/gripper_design_2/suction_rotation_updated.dae" scale="0.001 0.001 0.001"/>
      </geometry>
      <material name="White">
        <color rgba="0.588235294118 0.588235294118 0.588235294118 1.0"/>
      </material>
    </visual>
    <!--collision>
        <origin rpy="0 0 0" xyz="0.00 -0.027 0.0"/>
        <geometry>
          <mesh filename="package://iitktcs_robot_description/meshes/gripper_design_2/suction_rotation_updated.STL" scale="0.001 0.001 0.001"/>
        </geometry>
      </collision-->
    <inertial>
      <mass value="1"/>
      <inertia ixx="1" ixy="0.0" ixz="0.0" iyy="1" iyz="0.0" izz="1"/>
    </inertial>
  </link>
  <joint name="schubert_bellow_joint" type="fixed">
    <parent link="suction_base_link"/>
    <child link="bellow_link"/>
    <origin rpy="0 0 0" xyz="-0.002 -0.03 0.002"/>
  </joint>
  <link name="bellow_link">
    <visual>
      <origin rpy="0 0 0" xyz="-0.02 -0.027 -0.0225"/>
      <geometry>
        <mesh filename="package://iitktcs_robot_description/meshes/gripper_design_2/schubert_bellow.dae" scale="0.001 0.001 0.001"/>
      </geometry>
      <material name="White">
        <color rgba="0.588235294118 0.588235294118 0.588235294118 1.0"/>
      </material>
    </visual>
    <!--collision>
        <origin rpy="0 0 0" xyz="-0.02 -0.027 -0.0225"/>
        <geometry>
          <mesh filename="package://iitktcs_robot_description/meshes/gripper_design_2/schubert_bellow.stl" scale="0.001 0.001 0.001"/>
        </geometry>
      </collision-->
    <inertial>
      <mass value="1"/>
      <inertia ixx="1" ixy="0.0" ixz="0.0" iyy="1" iyz="0.0" izz="1"/>
    </inertial>
  </link>
  <!-- end-effector links -->
  <!-- Measurements from real gripper system. All measurements are from ee_link.
	- gripper measurement is taken till the central screw of the square finger plates
 	- gripper eef length 	45.5cm = 	model 44.5cm
	- gripper open length 	39cm = 		model not considered
	- gripper height 	2cm = 		model 2cm

	- suction measurement is taken till the blue colored suction bellow opening (not pressed the bellow)
	- suction bend length 	37cm = 	model 36.7cm
	- suction bend height 	-6cm = 	model -5cm
	- suction stght length 	43cm =	model 42.5

	- suction measurement is taken till the blue colored suction bellow opening (not pressed the bellow). Readings are for suction bend inside at 45 degrees
	- suction inside bend 45 length 41.4cm 	= model 41.4cm
	- suction inside bend 45 height -5cm	= model -4.5cm
	-->
  <joint name="suction_bend_joint" type="fixed">
    <origin rpy="0 0 0" xyz="0.324 -0.06 0.0"/>
    <parent link="gs_body_link"/>
    <child link="s_bend_eef_link"/>
  </joint>
  <link name="s_bend_eef_link"/>
  <joint name="gripper_eef_joint" type="fixed">
    <origin rpy="0 0 0" xyz="0.11 0.06 0.0"/>
    <parent link="s_bend_eef_link"/>
    <child link="gripper_eef_link"/>
  </joint>
  <link name="gripper_eef_link"/>
  <joint name="suction_mid_joint" type="fixed">
    <origin rpy="0 0 0.7853981625" xyz="-0.075 -0.05 0.0"/>
    <parent link="gripper_eef_link"/>
    <child link="s_mid_eef_link"/>
  </joint>
  <link name="s_mid_eef_link"/>
  <joint name="suction_tmp_joint" type="fixed">
    <origin rpy="0 0 -0.7853981625" xyz="0.0 0.0 0.0"/>
    <parent link="s_mid_eef_link"/>
    <child link="s_tmp_eef_link"/>
  </joint>
  <link name="s_tmp_eef_link"/>
  <joint name="suction_st_joint" type="fixed">
    <origin rpy="0 0 1.570796325" xyz="0.025 0.05 0.0"/>
    <parent link="s_tmp_eef_link"/>
    <child link="s_st_eef_link"/>
  </joint>
  <link name="s_st_eef_link"/>
  <!-- world will be root link-->
  <link name="world"/>
  <joint name="world_joint" type="fixed">
    <parent link="world"/>
    <child link="ground_base"/>
    <origin rpy="0.0 0.0 0.0" xyz="0.0 0.0 0.0"/>
  </joint>
</robot>

