<?xml version="1.0"?>
<!-- xacro for vgs mounted on the manipulator -->

<robot name="gripper_suction" xmlns:xacro="http://ros.org/wiki/xacro">

  <property name="M_PI" value="3.14159265" />
  <xacro:macro name="gripper_suction" params="prefix">


     <joint name="ee_suction_joint" type="fixed">
    <parent link="ee_ensenso_link"/>
    <child link="suction"/>
    <origin xyz="0.0 0 0.0" rpy="-${0.0*pi/180} -${0.0*pi/180} -${0*pi/180}" />
  </joint>

<link name="suction">
    <visual>
      <geometry>
        <cylinder length="0.46" radius="0.02"/>
      </geometry>
      <origin rpy="0 ${pi/2} 0" xyz="0.23 0 0"/>
      <material name="white">
        <color rgba="0.5 0.5 0.5 0.25"/>
      </material>
    </visual>
<collision>
<geometry>
        <cylinder length="0.46" radius="0.02"/>
      </geometry>
      <origin rpy="0 ${pi/2} 0" xyz="0.23 0 0"/>
</collision>
      <inertial>
<mass value="0.05"/>
<inertia ixx="1" ixy="0.0" ixz="0.0" iyy="1" iyz="0.0" izz="1"/>
</inertial>

  </link>






  <joint name="suction_suction2_joint" type="fixed">
    <parent link="suction"/>
    <child link="iitk_link"/>
    <origin xyz="0.46 0 0"/>
  </joint>

<link name="iitk_link">
    <visual>
      <geometry>
        <cylinder length="0.01" radius="0.02"/>
      </geometry>
      <origin rpy="0 ${pi/2} 0" xyz="0.005 0 0"/>
      <material name="white">
        <color rgba="0.5 0.5 0.5 1"/>
      </material>
    </visual>
<collision>
<geometry>
        <cylinder length="0.01" radius="0.02"/>
      </geometry>
      <origin rpy="0 ${pi/2} 0" xyz="0.005 0 0"/>
</collision>
      <inertial>
<mass value="0.05"/>
<inertia ixx="1" ixy="0.0" ixz="0.0" iyy="1" iyz="0.0" izz="1"/>
</inertial>

  </link>




    <joint name="suction_suction_joint" type="revolute">
    <parent link="iitk_link"/>
    <child link="suction_point"/>
    <origin rpy="0 0 0" xyz="0.01 0 0"/>
      <axis xyz="0 1 0" />
      <limit lower="${0}" upper="${pi/2}" effort="54.0" velocity="3.2"/>
      <dynamics damping="0.0" friction="0.0"/>
    </joint>

    <link name="suction_point">
    <visual>
        <geometry>
          <cylinder length="0.07" radius="0.02"/>
        </geometry>
      <origin rpy="0 ${pi/2} 0" xyz="0.035 0 0"/>
      <material name="blue">
        <color rgba="0 0 1 1"/>
        </material>
      </visual>
      <collision>
        <geometry>
          <cylinder length="0.07" radius="0.02"/>
        </geometry>
        <origin rpy="0 ${pi/2} 0" xyz="0.035 0 0"/>
      </collision>
      <inertial>
        <mass value="0.75"/>
        <inertia ixx="1" ixy="0.0" ixz="0.0" iyy="1" iyz="0.0" izz="1"/>
      </inertial>
      
    </link>

    <joint name="final_joint" type="revolute">
    <parent link="suction_point"/>
    <child link="nozele"/>
    <origin rpy="0 0 0" xyz="0.07 0 0"/>
      <axis xyz="0 1 0" />
      <limit lower="${0}" upper="${pi/2}" effort="54.0" velocity="3.2"/>
      <dynamics damping="0.0" friction="0.0"/>
    </joint>

    <link name="nozele">
    <visual>
        <geometry>
          <cylinder length="0.0" radius="0.0"/>
        </geometry>
      <origin rpy="0 ${pi/2} 0" xyz="0.0 0 0"/>
      <material name="blue">
        <color rgba="0 0 1 1"/>
        </material>
      </visual>
      <collision>
        <geometry>
          <cylinder length="0.00" radius="0.00"/>
        </geometry>
        <origin rpy="0 ${pi/2} 0" xyz="0.0 0 0"/>
      </collision>
      <inertial>
        <mass value="0.75"/>
        <inertia ixx="1" ixy="0.0" ixz="0.0" iyy="1" iyz="0.0" izz="1"/>
      </inertial>
      
    </link>


  </xacro:macro>
</robot>
